<?xml version="1.0"?>
<robot name="capstone_humanoid">

  <!-- Base Link (Torso) -->
  <link name="base_link">
    <visual>
      <geometry>
        <box size="0.2 0.3 0.5"/>
      </geometry>
      <material name="blue">
        <color rgba="0 0 0.8 1"/>
      </material>
    </visual>
    <collision>
      <geometry>
        <box size="0.2 0.3 0.5"/>
      </geometry>
    </collision>
    <inertial>
      <mass value="20"/>
      <inertia ixx="1.0" ixy="0.0" ixz="0.0" iyy="1.0" iyz="0.0" izz="1.0"/>
    </inertial>
  </link>

  <!-- Head Link -->
  <link name="head_link">
    <visual>
      <geometry>
        <sphere radius="0.15"/>
      </geometry>
      <material name="white">
        <color rgba="1 1 1 1"/>
      </material>
    </visual>
    <collision>
      <geometry>
        <sphere radius="0.15"/>
      </geometry>
    </collision>
    <inertial>
      <mass value="2"/>
      <inertia ixx="0.1" ixy="0.0" ixz="0.0" iyy="0.1" iyz="0.0" izz="0.1"/>
    </inertial>
  </link>

  <!-- Neck Joint (Fixed for simplicity) -->
  <joint name="neck_joint" type="fixed">
    <parent link="base_link"/>
    <child link="head_link"/>
    <origin xyz="0 0 0.35" rpy="0 0 0"/>
  </joint>

  <!-- Right Arm (Shoulder and Forearm) -->
  <link name="right_shoulder_link">
    <visual>
      <geometry>
        <sphere radius="0.08"/>
      </geometry>
      <material name="gray">
        <color rgba="0.5 0.5 0.5 1"/>
      </material>
    </visual>
    <collision>
      <geometry>
        <sphere radius="0.08"/>
      </geometry>
    </collision>
    <inertial>
      <mass value="0.5"/>
      <inertia ixx="0.01" ixy="0" ixz="0" iyy="0.01" iyz="0" izz="0.01"/>
    </inertial>
  </link>
  <joint name="right_shoulder_pitch_joint" type="revolute">
    <parent link="base_link"/>
    <child link="right_shoulder_link"/>
    <origin xyz="0 0.18 0.2" rpy="0 0 0"/>
    <axis xyz="0 1 0"/>
    <limit lower="-1.57" upper="1.57" effort="10" velocity="1.0"/>
  </joint>
  
  <link name="right_forearm_link">
    <visual>
      <geometry>
        <cylinder length="0.3" radius="0.04"/>
      </geometry>
      <material name="gray"/>
    </visual>
    <collision>
      <geometry>
        <cylinder length="0.3" radius="0.04"/>
      </geometry>
    </collision>
    <inertial>
      <mass value="0.5"/>
      <inertia ixx="0.01" ixy="0" ixz="0" iyy="0.01" iyz="0" izz="0.01"/>
    </inertial>
  </link>
  <joint name="right_elbow_joint" type="revolute">
    <parent link="right_shoulder_link"/>
    <child link="right_forearm_link"/>
    <origin xyz="0 0 -0.15" rpy="0 0 0"/>
    <axis xyz="0 1 0"/>
    <limit lower="-1.57" upper="1.57" effort="10" velocity="1.0"/>
  </joint>

  <!-- Material definitions -->
  <material name="blue"/>
  <material name="white"/>
  <material name="gray"/>

</robot>
